2024-10-12 06:18:36,468 INFO    Thread-11 (_run_job):38372 [wandb_setup.py:_flush():79] Current SDK version is 0.18.3
2024-10-12 06:18:36,468 INFO    Thread-11 (_run_job):38372 [wandb_setup.py:_flush():79] Configure stats pid to 38372
2024-10-12 06:18:36,468 INFO    Thread-11 (_run_job):38372 [wandb_setup.py:_flush():79] Loading settings from C:\Users\Admin\.config\wandb\settings
2024-10-12 06:18:36,468 INFO    Thread-11 (_run_job):38372 [wandb_setup.py:_flush():79] Loading settings from C:\Users\Admin\smai-m24-assignments-SohamVaishnav\assignments\3\wandb\settings
2024-10-12 06:18:36,468 INFO    Thread-11 (_run_job):38372 [wandb_setup.py:_flush():79] Loading settings from environment variables: {'project': 'Multi_label_HPT_optimSA', 'entity': 'soham-iiith', 'root_dir': 'C:\\Users\\Admin\\smai-m24-assignments-SohamVaishnav\\assignments\\3', 'sweep_id': '6qks7eqt', 'run_id': 'x10cerqy', 'sweep_param_path': 'C:\\Users\\Admin\\smai-m24-assignments-SohamVaishnav\\assignments\\3\\wandb\\sweep-6qks7eqt\\config-x10cerqy.yaml'}
2024-10-12 06:18:36,470 INFO    Thread-11 (_run_job):38372 [wandb_setup.py:_flush():79] Applying setup settings: {'mode': None, '_disable_service': None}
2024-10-12 06:18:36,470 INFO    Thread-11 (_run_job):38372 [wandb_setup.py:_flush():79] Inferring run settings from compute environment: {'program_relpath': 'assignments\\3\\a3.py', 'program_abspath': 'c:\\Users\\Admin\\smai-m24-assignments-SohamVaishnav\\assignments\\3\\a3.py', 'program': 'c:\\Users\\Admin\\smai-m24-assignments-SohamVaishnav\\assignments\\3\\a3.py'}
2024-10-12 06:18:36,470 INFO    Thread-11 (_run_job):38372 [wandb_setup.py:_flush():79] Applying login settings: {}
2024-10-12 06:18:36,470 INFO    Thread-11 (_run_job):38372 [wandb_init.py:_log_setup():532] Logging user logs to C:\Users\Admin\smai-m24-assignments-SohamVaishnav\assignments\3\wandb\run-20241012_061836-x10cerqy\logs\debug.log
2024-10-12 06:18:36,470 INFO    Thread-11 (_run_job):38372 [wandb_init.py:_log_setup():533] Logging internal logs to C:\Users\Admin\smai-m24-assignments-SohamVaishnav\assignments\3\wandb\run-20241012_061836-x10cerqy\logs\debug-internal.log
2024-10-12 06:18:36,470 INFO    Thread-11 (_run_job):38372 [wandb_init.py:init():617] calling init triggers
2024-10-12 06:18:36,470 INFO    Thread-11 (_run_job):38372 [wandb_init.py:init():624] wandb.init called with sweep_config: {'activations': 'sigmoid', 'batch_size': 64, 'epochs': 500, 'layers': [20, 10, 8], 'lr': 0.0001, 'optimizer': 'sgd', 'thresh': 0.3}
config: {}
2024-10-12 06:18:36,470 INFO    Thread-11 (_run_job):38372 [wandb_init.py:init():667] starting backend
2024-10-12 06:18:36,470 INFO    Thread-11 (_run_job):38372 [wandb_init.py:init():671] sending inform_init request
2024-10-12 06:18:36,476 INFO    Thread-11 (_run_job):38372 [backend.py:_multiprocessing_setup():104] multiprocessing start_methods=spawn, using: spawn
2024-10-12 06:18:36,479 INFO    Thread-11 (_run_job):38372 [wandb_init.py:init():684] backend started and connected
2024-10-12 06:18:36,491 INFO    Thread-11 (_run_job):38372 [wandb_run.py:_config_callback():1394] config_cb None None {'activations': 'sigmoid', 'batch_size': 64, 'epochs': 500, 'layers': [20, 10, 8], 'lr': 0.0001, 'optimizer': 'sgd', 'thresh': 0.3}
2024-10-12 06:18:36,491 INFO    Thread-11 (_run_job):38372 [wandb_init.py:init():779] updated telemetry
2024-10-12 06:18:36,530 INFO    Thread-11 (_run_job):38372 [wandb_init.py:init():812] communicating run to backend with 90.0 second timeout
2024-10-12 06:18:36,863 INFO    Thread-11 (_run_job):38372 [wandb_init.py:init():863] starting run threads in backend
2024-10-12 06:18:37,073 INFO    Thread-11 (_run_job):38372 [wandb_run.py:_console_start():2465] atexit reg
2024-10-12 06:18:37,074 INFO    Thread-11 (_run_job):38372 [wandb_run.py:_redirect():2313] redirect: wrap_raw
2024-10-12 06:18:37,074 INFO    Thread-11 (_run_job):38372 [wandb_run.py:_redirect():2378] Wrapping output streams.
2024-10-12 06:18:37,074 INFO    Thread-11 (_run_job):38372 [wandb_run.py:_redirect():2403] Redirects installed.
2024-10-12 06:18:37,078 INFO    Thread-11 (_run_job):38372 [wandb_init.py:init():907] run started, returning control to user process
2024-10-12 06:19:53,378 INFO    Thread-11 (_run_job):38372 [wandb_run.py:_finish():2164] finishing run soham-iiith/Multi_label_HPT_optimSA/x10cerqy
2024-10-12 06:19:53,378 INFO    Thread-11 (_run_job):38372 [wandb_run.py:_atexit_cleanup():2428] got exitcode: 0
2024-10-12 06:19:53,378 INFO    Thread-11 (_run_job):38372 [wandb_run.py:_restore():2410] restore
2024-10-12 06:19:53,378 INFO    Thread-11 (_run_job):38372 [wandb_run.py:_restore():2416] restore done
2024-10-12 06:43:12,775 INFO    Thread-10 (_heartbeat):38372 [retry.py:__call__():172] Retry attempt failed:
Traceback (most recent call last):
  File "C:\Users\Admin\AppData\Local\Programs\Python\Python311\Lib\site-packages\urllib3\connection.py", line 174, in _new_conn
    conn = connection.create_connection(
           ^^^^^^^^^^^^^^^^^^^^^^^^^^^^^
  File "C:\Users\Admin\AppData\Local\Programs\Python\Python311\Lib\site-packages\urllib3\util\connection.py", line 72, in create_connection
    for res in socket.getaddrinfo(host, port, family, socket.SOCK_STREAM):
               ^^^^^^^^^^^^^^^^^^^^^^^^^^^^^^^^^^^^^^^^^^^^^^^^^^^^^^^^^^
  File "C:\Users\Admin\AppData\Local\Programs\Python\Python311\Lib\socket.py", line 962, in getaddrinfo
    for res in _socket.getaddrinfo(host, port, family, type, proto, flags):
               ^^^^^^^^^^^^^^^^^^^^^^^^^^^^^^^^^^^^^^^^^^^^^^^^^^^^^^^^^^^
socket.gaierror: [Errno 11001] getaddrinfo failed

During handling of the above exception, another exception occurred:

Traceback (most recent call last):
  File "C:\Users\Admin\AppData\Local\Programs\Python\Python311\Lib\site-packages\urllib3\connectionpool.py", line 715, in urlopen
    httplib_response = self._make_request(
                       ^^^^^^^^^^^^^^^^^^^
  File "C:\Users\Admin\AppData\Local\Programs\Python\Python311\Lib\site-packages\urllib3\connectionpool.py", line 404, in _make_request
    self._validate_conn(conn)
  File "C:\Users\Admin\AppData\Local\Programs\Python\Python311\Lib\site-packages\urllib3\connectionpool.py", line 1060, in _validate_conn
    conn.connect()
  File "C:\Users\Admin\AppData\Local\Programs\Python\Python311\Lib\site-packages\urllib3\connection.py", line 363, in connect
    self.sock = conn = self._new_conn()
                       ^^^^^^^^^^^^^^^^
  File "C:\Users\Admin\AppData\Local\Programs\Python\Python311\Lib\site-packages\urllib3\connection.py", line 186, in _new_conn
    raise NewConnectionError(
urllib3.exceptions.NewConnectionError: <urllib3.connection.HTTPSConnection object at 0x0000016BED2E1910>: Failed to establish a new connection: [Errno 11001] getaddrinfo failed

During handling of the above exception, another exception occurred:

Traceback (most recent call last):
  File "C:\Users\Admin\AppData\Local\Programs\Python\Python311\Lib\site-packages\requests\adapters.py", line 486, in send
    resp = conn.urlopen(
           ^^^^^^^^^^^^^
  File "C:\Users\Admin\AppData\Local\Programs\Python\Python311\Lib\site-packages\urllib3\connectionpool.py", line 801, in urlopen
    retries = retries.increment(
              ^^^^^^^^^^^^^^^^^^
  File "C:\Users\Admin\AppData\Local\Programs\Python\Python311\Lib\site-packages\urllib3\util\retry.py", line 594, in increment
    raise MaxRetryError(_pool, url, error or ResponseError(cause))
urllib3.exceptions.MaxRetryError: HTTPSConnectionPool(host='api.wandb.ai', port=443): Max retries exceeded with url: /graphql (Caused by NewConnectionError('<urllib3.connection.HTTPSConnection object at 0x0000016BED2E1910>: Failed to establish a new connection: [Errno 11001] getaddrinfo failed'))

During handling of the above exception, another exception occurred:

Traceback (most recent call last):
  File "C:\Users\Admin\AppData\Local\Programs\Python\Python311\Lib\site-packages\wandb\sdk\lib\retry.py", line 131, in __call__
    result = self._call_fn(*args, **kwargs)
             ^^^^^^^^^^^^^^^^^^^^^^^^^^^^^^
  File "C:\Users\Admin\AppData\Local\Programs\Python\Python311\Lib\site-packages\wandb\sdk\internal\internal_api.py", line 347, in execute
    return self.client.execute(*args, **kwargs)  # type: ignore
           ^^^^^^^^^^^^^^^^^^^^^^^^^^^^^^^^^^^^
  File "C:\Users\Admin\AppData\Local\Programs\Python\Python311\Lib\site-packages\wandb\vendor\gql-0.2.0\wandb_gql\client.py", line 52, in execute
    result = self._get_result(document, *args, **kwargs)
             ^^^^^^^^^^^^^^^^^^^^^^^^^^^^^^^^^^^^^^^^^^^
  File "C:\Users\Admin\AppData\Local\Programs\Python\Python311\Lib\site-packages\wandb\vendor\gql-0.2.0\wandb_gql\client.py", line 60, in _get_result
    return self.transport.execute(document, *args, **kwargs)
           ^^^^^^^^^^^^^^^^^^^^^^^^^^^^^^^^^^^^^^^^^^^^^^^^^
  File "C:\Users\Admin\AppData\Local\Programs\Python\Python311\Lib\site-packages\wandb\sdk\lib\gql_request.py", line 58, in execute
    request = self.session.post(self.url, **post_args)
              ^^^^^^^^^^^^^^^^^^^^^^^^^^^^^^^^^^^^^^^^
  File "C:\Users\Admin\AppData\Local\Programs\Python\Python311\Lib\site-packages\requests\sessions.py", line 637, in post
    return self.request("POST", url, data=data, json=json, **kwargs)
           ^^^^^^^^^^^^^^^^^^^^^^^^^^^^^^^^^^^^^^^^^^^^^^^^^^^^^^^^^
  File "C:\Users\Admin\AppData\Local\Programs\Python\Python311\Lib\site-packages\requests\sessions.py", line 589, in request
    resp = self.send(prep, **send_kwargs)
           ^^^^^^^^^^^^^^^^^^^^^^^^^^^^^^
  File "C:\Users\Admin\AppData\Local\Programs\Python\Python311\Lib\site-packages\requests\sessions.py", line 703, in send
    r = adapter.send(request, **kwargs)
        ^^^^^^^^^^^^^^^^^^^^^^^^^^^^^^^
  File "C:\Users\Admin\AppData\Local\Programs\Python\Python311\Lib\site-packages\requests\adapters.py", line 519, in send
    raise ConnectionError(e, request=request)
requests.exceptions.ConnectionError: HTTPSConnectionPool(host='api.wandb.ai', port=443): Max retries exceeded with url: /graphql (Caused by NewConnectionError('<urllib3.connection.HTTPSConnection object at 0x0000016BED2E1910>: Failed to establish a new connection: [Errno 11001] getaddrinfo failed'))
2024-10-12 06:44:19,834 INFO    Thread-11 (_run_job):38372 [wandb_run.py:_footer_history_summary_info():4049] rendering history
2024-10-12 06:44:19,836 INFO    Thread-11 (_run_job):38372 [wandb_run.py:_footer_history_summary_info():4081] rendering summary
2024-10-12 06:44:19,858 INFO    Thread-11 (_run_job):38372 [wandb_run.py:_footer_sync_info():4008] logging synced files
